Workbook
Name Discount_Rate: 'Integrated DCF Model'!$E$10
Name Discount_Rate: #REF!
Name IQ_CH: 110000
Name IQ_CQ: 5000
Name IQ_CY: 10000
Name IQ_DAILY: 500000
Name IQ_FH: 100000
Name IQ_FQ: 500
Name IQ_FWD_CY: 10001
Name IQ_FWD_CY1: 10002
Name IQ_FWD_CY2: 10003
Name IQ_FWD_FY: 1001
Name IQ_FWD_FY1: 1002
Name IQ_FWD_FY2: 1003
Name IQ_FWD_Q: 501
Name IQ_FWD_Q1: 502
Name IQ_FWD_Q2: 503
Name IQ_FY: 1000
Name IQ_LATESTK: 1000
Name IQ_LATESTQ: 500
Name IQ_LTM: 2000
Name IQ_LTMMONTH: 120000
Name IQ_MONTH: 15000
Name IQ_NTM: 6000
Name IQ_TODAY: 0
Name IQ_WEEK: 50000
Name IQ_YTD: 3000
Name IQ_YTDMONTH: 130000
Name Tax: [1]DCF!$D$44

Sheet Revenue Build & Growth Drivers
C2: ="Revenue Build & Growth Drivers For "&D5 -> Revenue Build & Growth Drivers For TopBuild Corp.
C3: $ in thousands except per unit
C5: Company Name | D5: TopBuild Corp.
C6: Ticker | D6: BLD
C7: Valuation Date | D7: 45394
C8: Latest Adj. Closing Share Price Date | D8: 45393
C9: Latest Adj. Closing Share Price | D9: 421.45
C11: Revenue Projection | D11: Historical | G11: Projected
D12: ='Financial Statement Model'!D12 -> 44561 | E12: ='Financial Statement Model'!E12 -> 44926 | F12: ='Financial Statement Model'!F12 -> 45291 | G12: ='Financial Statement Model'!G12 -> 45657 | H12: ='Financial Statement Model'!H12 -> 46022 | I12: ='Financial Statement Model'!I12 -> 46387 | J12: ='Financial Statement Model'!J12 -> 46752 | K12: ='Financial Statement Model'!K12 -> 47118
C14: Total Revenues | D14: =+D20+D23-D26 -> 3486207 | E14: =+E20+E23-E26 -> 5008744 | F14: =+F20+F23-F26 -> 5194694 | G14: =+G20+G23-G26 -> 5387941.2 | H14: =+H20+H23-H26 -> 5546043.1 | I14: =+I20+I23-I26 -> 5726018.4 | J14: =+J20+J23-J26 -> 5949773.4 | K14: =+K20+K23-K26 -> 6205869.8
C15: % growth | E15: =+E14/D14-1 -> 0.43673167 | F15: =+F14/E14-1 -> 0.037125076 | G15: =+G14/F14-1 -> 0.037200876 | H15: =+H14/G14-1 -> 0.029343659 | I15: =+I14/H14-1 -> 0.032451131 | J15: =+J14/I14-1 -> 0.039076893 | K15: =+K14/J14-1 -> 0.043043048
C17: Segmental Revenue Schedule | D17: Historical | G17: Projected
D18: ='Financial Statement Model'!D12 -> 44561 | E18: ='Financial Statement Model'!E12 -> 44926 | F18: ='Financial Statement Model'!F12 -> 45291 | G18: ='Financial Statement Model'!G12 -> 45657 | H18: ='Financial Statement Model'!H12 -> 46022 | I18: ='Financial Statement Model'!I12 -> 46387 | J18: ='Financial Statement Model'!J12 -> 46752 | K18: ='Financial Statement Model'!K12 -> 47118
C20: Installation Revenue | D20: 2378401 | E20: 2969978 | F20: 3188232 | G20: =+F20*(1+G21) -> 3331702.4 | H20: =+G20*(1+H21) -> 3448312 | I20: =+H20*(1+I21) -> 3569002.9 | J20: =+I20*(1+J21) -> 3729608.1 | K20: =+J20*(1+K21) -> 3897440.4
C21: % growth | E21: =+E20/D20-1 -> 0.24872887 | F21: =+F20/E20-1 -> 0.07348674 | G21: =+SUM(G34:G36) -> 0.045 | H21: =+SUM(H34:H36) -> 0.035 | I21: =+SUM(I34:I36) -> 0.035 | J21: =+SUM(J34:J36) -> 0.045 | K21: =+SUM(K34:K36) -> 0.045
C23: Specialty Distribution | D23: 1287176 | E23: 2278261 | F23: 2268339 | G23: =+F23*(1+G24) -> 2325047.5 | H23: =+G23*(1+H24) -> 2371548.4 | I23: =+H23*(1+I24) -> 2442694.9 | J23: =+I23*(1+J24) -> 2515975.7 | K23: =+J23*(1+K24) -> 2616614.8
C24: % growth | E24: =+E23/D23-1 -> 0.76996852 | F24: =+F23/E23-1 -> -0.0043550761 | G24: =+SUM(G39:G41) -> 0.025 | H24: =+SUM(H39:H41) -> 0.02 | I24: =+SUM(I39:I41) -> 0.03 | J24: =+SUM(J39:J41) -> 0.03 | K24: =+SUM(K39:K41) -> 0.04
C26: Intercompany Eliminations | D26: 179370 | E26: 239495 | F26: 261877 | G26: =+G27*(G23+G20) -> 268808.75 | H26: =+H27*(H23+H20) -> 273817.38 | I26: =+I27*(I23+I20) -> 285679.38 | J26: =+J27*(J23+J20) -> 295810.35 | K26: =+K27*(K23+K20) -> 308185.36
C27: Eliminations as % of Gross Revenue | D27: =+D26/(D23+D20) -> 0.048933633 | E27: =+E26/(E23+E20) -> 0.045633402 | F27: =+F26/(F23+F20) -> 0.047992961 | G27: =+AVERAGE(D27:F27) -> 0.047519999 | H27: =+AVERAGE(E27:G27) -> 0.047048787 | I27: =+AVERAGE(F27:H27) -> 0.047520582 | J27: =+AVERAGE(G27:I27) -> 0.047363123 | K27: =+AVERAGE(H27:J27) -> 0.047310831
C29: Growth Driver Assumptions
C31: Segment Revenue Growth Drivers | D31: Historical | G31: Projected
D32: ='Financial Statement Model'!D12 -> 44561 | E32: ='Financial Statement Model'!E12 -> 44926 | F32: ='Financial Statement Model'!F12 -> 45291 | G32: ='Financial Statement Model'!G12 -> 45657 | H32: ='Financial Statement Model'!H12 -> 46022 | I32: ='Financial Statement Model'!I12 -> 46387 | J32: ='Financial Statement Model'!J12 -> 46752 | K32: ='Financial Statement Model'!K12 -> 47118
C33: % growth attribution for Installation segment
C34: Selling prices | E34: 0.122 | F34: 0.036 | G34: 0.015 | H34: 0.005 | I34: 0.005 | J34: 0.005 | K34: 0.005
C35: Volumes | E35: 0.092 | F35: 0 | G35: -0.005 | H35: -0.005 | I35: 0 | J35: 0.01 | K35: 0.01
C36: Acquisitions | E36: 0.034 | F36: 0.036 | G36: 0.035 | H36: 0.035 | I36: 0.03 | J36: 0.03 | K36: 0.03
C38: % growth attribution for Specialty Distribution segment
C39: Selling prices | E39: 0.158 | F39: 0.011 | G39: 0.015 | H39: 0.005 | I39: 0.005 | J39: 0.005 | K39: 0.005
C40: Volumes | E40: -0.006 | F40: -0.016 | G40: -0.005 | H40: 0 | I40: 0.01 | J40: 0.01 | K40: 0.02
C41: Acquisitions | E41: 0.618 | F41: 0 | G41: 0.015 | H41: 0.015 | I41: 0.015 | J41: 0.015 | K41: 0.015
C43: General Growth Drivers | D43: Historical | G43: Projected
D44: ='Financial Statement Model'!D12 -> 44561 | E44: ='Financial Statement Model'!E12 -> 44926 | F44: ='Financial Statement Model'!F12 -> 45291 | G44: ='Financial Statement Model'!G12 -> 45657 | H44: ='Financial Statement Model'!H12 -> 46022 | I44: ='Financial Statement Model'!I12 -> 46387 | J44: ='Financial Statement Model'!J12 -> 46752 | K44: ='Financial Statement Model'!K12 -> 47118
C45: Operating Expenses
C46: Gross Profit Margin | D46: ='Financial Statement Model'!D35 -> 0.27949832 | E46: ='Financial Statement Model'!E35 -> 0.29682471 | F46: ='Financial Statement Model'!F35 -> 0.30874196 | G46: 0.31 | H46: 0.315 | I46: 0.317 | J46: 0.319 | K46: 0.321
C47: SG&A % Revenue | D47: ='Financial Statement Model'!D36 -> 0.13828697 | E47: ='Financial Statement Model'!E36 -> 0.1374107 | F47: ='Financial Statement Model'!F36 -> 0.13644596 | G47: 0.135 | H47: 0.135 | I47: 0.135 | J47: 0.135 | K47: 0.135
C48: Other Operating Expense % of Revenue | D48: ='Financial Statement Model'!D37 -> 0 | E48: ='Financial Statement Model'!E37 -> 0 | F48: ='Financial Statement Model'!F37 -> 0 | G48: 0 | H48: 0 | I48: 0 | J48: 0 | K48: 0
C49: Days Sales Outstanding | D49: ='Financial Statement Model'!D118 -> 69.982343 | E49: ='Financial Statement Model'!E118 -> 60.926635 | F49: ='Financial Statement Model'!F118 -> 56.141572 | G49: 55 | H49: 55 | I49: 55 | J49: 55 | K49: 55
C50: Inventory Turnover | E50: ='Financial Statement Model'!E129 -> 8.0293473 | F50: ='Financial Statement Model'!F129 -> 9.8452668 | G50: 10 | H50: 10 | I50: 10 | J50: 10 | K50: 10
C51: Days Payables Outstanding | D51: =+'Financial Statement Model'!D145 -> 67.12258 | E51: =+'Financial Statement Model'!E145 -> 50.481359 | F51: =+'Financial Statement Model'!F145 -> 47.731701 | G51: 50 | H51: 50 | I51: 50 | J51: 50 | K51: 50
C53: Acquisition spend allocation to:
...

Sheet Financial Statement Model
C2: ="Financial Statement Model For "&D5 -> Financial Statement Model For TopBuild Corp.
C3: $ in thousands except per share
C5: Company Name | D5: ='Revenue Build & Growth Drivers'!D5 -> TopBuild Corp. | G5: Circ toggle (1=on, 0=off) | J5: 1 | O5: Circ toggle: 1 = circularity on (interest based on average balances)
C6: Ticker | D6: ='Revenue Build & Growth Drivers'!D6 -> BLD | O6: Circ toggle: 0 = circularity off (interest income/expense set to zero)
C7: Valuation Date | D7: ='Revenue Build & Growth Drivers'!D7 -> 45394
C8: Latest Adj. Closing Share Price Date | D8: ='Revenue Build & Growth Drivers'!D8 -> 45393
C9: Latest Adj. Closing Share Price | D9: ='Revenue Build & Growth Drivers'!D9 -> 421.45
C11: Income Statement | D11: Historical | G11: Projected | M11: 5 Year
D12: 44561 | E12: =EOMONTH(D12,12) -> 44926 | F12: =EOMONTH(E12,12) -> 45291 | G12: =EOMONTH(F12,12) -> 45657 | H12: =EOMONTH(G12,12) -> 46022 | I12: =EOMONTH(H12,12) -> 46387 | J12: =EOMONTH(I12,12) -> 46752 | K12: =EOMONTH(J12,12) -> 47118 | M12: CAGR
C14: Total Revenues | D14: 3486207 | E14: 5008744 | F14: 5194694 | G14: =+F14*(1+G34) -> 5387941.2 | H14: =+G14*(1+H34) -> 5546043.1 | I14: =+H14*(1+I34) -> 5726018.4 | J14: =+I14*(1+J34) -> 5949773.4 | K14: =+J14*(1+K34) -> 6205869.8 | M14: =+_xlfn.RRI(YEAR($K$12)-YEAR($F$12),F14,K14) -> 0.036211812
C15: Less: Cost of Sales | D15: 2511818 | E15: 3522025 | F15: 3590874 | G15: =+G14-G16 -> 3717679.4 | H15: =+H14-H16 -> 3799039.5 | I15: =+I14-I16 -> 3910870.6 | J15: =+J14-J16 -> 4051795.7 | K15: =+K14-K16 -> 4213785.6
C16: Gross Profit | D16: 974389 | E16: 1486719 | F16: 1603820 | G16: =+G14*G35 -> 1670261.8 | H16: =+H14*H35 -> 1747003.6 | I16: =+I14*I35 -> 1815147.8 | J16: =+J14*J35 -> 1897977.7 | K16: =+K14*K35 -> 1992084.2 | M16: =+_xlfn.RRI(YEAR($K$12)-YEAR($F$12),F16,K16) -> 0.04431235
C17: SG&A Expense | D17: 482097 | E17: 688255 | F17: 708795 | G17: =+G14*G36 -> 727372.06 | H17: =+H14*H36 -> 748715.81 | I17: =+I14*I36 -> 773012.49 | J17: =+J14*J36 -> 803219.42 | K17: =+K14*K36 -> 837792.43
C18: Other Operating Expense | D18: 0 | E18: 0 | F18: 0 | G18: =+G37*G14 -> 0 | H18: =+H37*H14 -> 0 | I18: =+I37*I14 -> 0 | J18: =+J37*J14 -> 0 | K18: =+K37*K14 -> 0
C19: Operating Profit (EBIT) | D19: 492292 | E19: 798464 | F19: 895025 | G19: =+G16-G17-G18 -> 942889.7 | H19: =+H16-H17-H18 -> 998287.75 | I19: =+I16-I17-I18 -> 1042135.4 | J19: =+J16-J17-J18 -> 1094758.3 | K19: =+K16-K17-K18 -> 1154291.8 | M19: =+_xlfn.RRI(YEAR($K$12)-YEAR($F$12),F19,K19) -> 0.052194647
C20: Nonoperating Income | D20: -1352 | E20: 1687 | F20: 21272 | G20: =G279 -> 0 | H20: =H279 -> 0 | I20: =I279 -> 0 | J20: =J279 -> 0 | K20: =K279 -> 0
C21: Interest Expense | D21: 29143 | E21: 56716 | F21: 74614 | G21: =G260+G274+G285 -> 0 | H21: =H260+H274+H285 -> 0 | I21: =I260+I274+I285 -> 0 | J21: =J260+J274+J285 -> 0 | K21: =K260+K274+K285 -> 0
C22: Unusual Expenses | D22: 28354 | E22: 1300 | F22: 16200 | G22: 0 | H22: 0 | I22: 0 | J22: 0 | K22: 0
C23: Pre-tax Profit | D23: 433443 | E23: 742135 | F23: 825483 | G23: =+G19+G20-G21-G22 -> 942889.7 | H23: =+H19+H20-H21-H22 -> 998287.75 | I23: =+I19+I20-I21-I22 -> 1042135.4 | J23: =+J19+J20-J21-J22 -> 1094758.3 | K23: =+K19+K20-K21-K22 -> 1154291.8 | M23: =+_xlfn.RRI(YEAR($K$12)-YEAR($F$12),F23,K23) -> 0.069353991
C24: Income Taxes | D24: 109427 | E24: 186146 | F24: 211229 | G24: =+G23*G41 -> 241271.65 | H24: =+H23*H41 -> 255447.2 | I24: =+I23*I41 -> 266667.16 | J24: =+J23*J41 -> 280132.61 | K24: =+K23*K41 -> 295366.35
C25: Minority interest | D25: 0 | E25: 0 | F25: 0 | G25: =G225 -> 0 | H25: =H225 -> 0 | I25: =I225 -> 0 | J25: =J225 -> 0 | K25: =K225 -> 0
C26: Net Income | D26: 324016 | E26: 555989 | F26: 614254 | G26: =+G23-G24-G25 -> 701618.05 | H26: =+H23-H24-H25 -> 742840.55 | I26: =+I23-I24-I25 -> 775468.19 | J26: =+J23-J24-J25 -> 814625.71 | K26: =+K23-K24-K25 -> 858925.44 | M26: =+_xlfn.RRI(YEAR($K$12)-YEAR($F$12),F26,K26) -> 0.069353991
C28: Depreciation and Amortization | D28: 79390 | E28: 123335 | F28: 132878 | G28: =+G183+G160+G302 -> 0 | H28: =+H183+H160+H302 -> 0 | I28: =+I183+I160+I302 -> 0 | J28: =+J183+J160+J302 -> 0 | K28: =+K183+K160+K302 -> 0
C29: EBITDA | D29: 571682 | E29: 921799 | F29: 1027903 | G29: =+G19+G28 -> 942889.7 | H29: =+H19+H28 -> 998287.75 | I29: =+I19+I28 -> 1042135.4 | J29: =+J19+J28 -> 1094758.3 | K29: =+K19+K28 -> 1154291.8 | M29: =+_xlfn.RRI(YEAR($K$12)-YEAR($F$12),F29,K29) -> 0.023464291
C31: Stock Compensation and Exercise of Options | D31: 11316 | E31: 12310 | F31: 15838 | G31: =+AVERAGE(D31:F31) -> 13154.667 | H31: =+AVERAGE(E31:G31) -> 13767.556 | I31: =+AVERAGE(F31:H31) -> 14253.407 | J31: =+AVERAGE(G31:I31) -> 13725.21 | K31: =+AVERAGE(H31:J31) -> 13915.391
C33: Growth Rates and Margins
C34: Revenue Growth | E34: =+E14/D14-1 -> 0.43673167 | F34: =+F14/E14-1 -> 0.037125076 | G34: =+'Revenue Build & Growth Drivers'!G15 -> 0.037200876 | H34: =+'Revenue Build & Growth Drivers'!H15 -> 0.029343659 | I34: =+'Revenue Build & Growth Drivers'!I15 -> 0.032451131 | J34: =+'Revenue Build & Growth Drivers'!J15 -> 0.039076893 | K34: =+'Revenue Build & Growth Drivers'!K15 -> 0.043043048
C35: Gross Profit Margin | D35: =+D16/D14 -> 0.27949832 | E35: =+E16/E14 -> 0.29682471 | F35: =+F16/F14 -> 0.30874196 | G35: ='Revenue Build & Growth Drivers'!G46 -> 0.31 | H35: ='Revenue Build & Growth Drivers'!H46 -> 0.315 | I35: ='Revenue Build & Growth Drivers'!I46 -> 0.317 | J35: ='Revenue Build & Growth Drivers'!J46 -> 0.319 | K35: ='Revenue Build & Growth Drivers'!K46 -> 0.321
C36: SG&A % of Revenue | D36: =+D17/D14 -> 0.13828697 | E36: =+E17/E14 -> 0.1374107 | F36: =+F17/F14 -> 0.13644596 | G36: ='Revenue Build & Growth Drivers'!G47 -> 0.135 | H36: ='Revenue Build & Growth Drivers'!H47 -> 0.135 | I36: ='Revenue Build & Growth Drivers'!I47 -> 0.135 | J36: ='Revenue Build & Growth Drivers'!J47 -> 0.135 | K36: ='Revenue Build & Growth Drivers'!K47 -> 0.135
C37: Other Operating Expense % of Revenue | D37: =+D18/D14 -> 0 | E37: =+E18/E14 -> 0 | F37: =+F18/F14 -> 0 | G37: ='Revenue Build & Growth Drivers'!G48 -> 0 | H37: ='Revenue Build & Growth Drivers'!H48 -> 0 | I37: ='Revenue Build & Growth Drivers'!I48 -> 0 | J37: ='Revenue Build & Growth Drivers'!J48 -> 0 | K37: ='Revenue Build & Growth Drivers'!K48 -> 0
C38: EBIT Margin | D38: =+D19/D14 -> 0.14121135 | E38: =+E19/E14 -> 0.15941402 | F38: =+F19/F14 -> 0.172296 | G38: =+G19/G14 -> 0.175 | H38: =+H19/H14 -> 0.18 | I38: =+I19/I14 -> 0.182 | J38: =+J19/J14 -> 0.184 | K38: =+K19/K14 -> 0.186
C39: EBITDA Margin | D39: =+D29/D14 -> 0.16398395 | E39: =+E29/E14 -> 0.18403795 | F39: =+F29/F14 -> 0.19787556 | G39: =+G29/G14 -> 0.175 | H39: =+H29/H14 -> 0.18 | I39: =+I29/I14 -> 0.182 | J39: =+J29/J14 -> 0.184 | K39: =+K29/K14 -> 0.186
C40: Profit Margin | D40: =+D26/D14 -> 0.092942272 | E40: =+E26/E14 -> 0.11100368 | F40: =+F26/F14 -> 0.11824643 | G40: =+G26/G14 -> 0.13022007 | H40: =+H26/H14 -> 0.13394064 | I40: =+I26/I14 -> 0.13542887 | J40: =+J26/J14 -> 0.1369171 | K40: =+K26/K14 -> 0.13840533
C41: Effective Tax Rate | D41: =+D24/D23 -> 0.25245995 | E41: =+E24/E23 -> 0.25082498 | F41: =+F24/F23 -> 0.25588534 | G41: =+IF(F41<0,AVERAGEIFS(D41:F41,D41:F41,">0"),F41) -> 0.25588534 | H41: =+G41 -> 0.25588534 | I41: =+H41 -> 0.25588534 | J41: =+I41 -> 0.25588534 | K41: =+J41 -> 0.25588534
C43: Balance Sheet | D43: Historical | G43: Projected | M43: 5 Year
D44: =+D$12 -> 44561 | E44: =+E$12 -> 44926 | F44: =+F$12 -> 45291 | G44: =+G$12 -> 45657 | H44: =+H$12 -> 46022 | I44: =+I$12 -> 46387 | J44: =+J$12 -> 46752 | K44: =+K$12 -> 47118 | M44: CAGR
C46: Cash & Short-Term Investments | D46: 139779 | E46: 240069 | F46: 848565 | G46: =+F46+G103 -> 848565 | H46: =+G46+H103 -> 848565 | I46: =+H46+I103 -> 848565 | J46: =+I46+J103 -> 848565 | K46: =+J46+K103 -> 848565 | M46: =+_xlfn.RRI(YEAR($K$12)-YEAR($F$12),F46,K46) -> 0
C47: Short-Term Receivables | D47: 668419 | E47: 836071 | F47: 799009
C48: Inventories | D48: 352801 | E48: 438644 | F48: 364731
C49: Other Current Assets | D49: 26692 | E49: 34257 | F49: 36939 | O49: Grows with Revenue.
...

Sheet Integrated DCF Model
C2: ="Discounted Cash Flow Model For "&D5 -> Discounted Cash Flow Model For TopBuild Corp.
C3: $ in thousands except per share | J3: Values
C5: Company Name | D5: ='Revenue Build & Growth Drivers'!D5 -> TopBuild Corp. | G5: Basic Shares Outstanding | J5: =+D66 -> 31775.877
C6: Ticker | D6: ='Revenue Build & Growth Drivers'!D6 -> BLD | G6: Fully Diluted Shares Outstanding | J6: =+D71 -> 32100.077
C7: Valuation Date | D7: ='Revenue Build & Growth Drivers'!D7 -> 45394 | G7: Discount Rate (WACC) | J7: =+'WACC Build'!D43 -> 0
C8: Latest Adj. Closing Share Price Date | D8: ='Revenue Build & Growth Drivers'!D8 -> 45393 | G8: Midyear Adjustment (1=on, 0=off) | J8: 0
C9: Latest Adj. Closing Share Price | D9: ='Revenue Build & Growth Drivers'!D9 -> 421.45
C11: Unlevered Free Cash Flow | E11: Historical | H11: Projected | N11: 5 Year
E12: ='Financial Statement Model'!D12 -> 44561 | F12: ='Financial Statement Model'!E12 -> 44926 | G12: ='Financial Statement Model'!F12 -> 45291 | H12: ='Financial Statement Model'!G12 -> 45657 | I12: ='Financial Statement Model'!H12 -> 46022 | J12: ='Financial Statement Model'!I12 -> 46387 | K12: ='Financial Statement Model'!J12 -> 46752 | L12: ='Financial Statement Model'!K12 -> 47118 | N12: CAGR
C14: Total Revenues | E14: =+'Financial Statement Model'!D14 -> 3486207 | F14: =+'Financial Statement Model'!E14 -> 5008744 | G14: =+'Financial Statement Model'!F14 -> 5194694 | H14: =+'Financial Statement Model'!G14 -> 5387941.2 | I14: =+'Financial Statement Model'!H14 -> 5546043.1 | J14: =+'Financial Statement Model'!I14 -> 5726018.4 | K14: =+'Financial Statement Model'!J14 -> 5949773.4 | L14: =+'Financial Statement Model'!K14 -> 6205869.8
C15: YoY Growth Rate (%) | F15: =+F14/E14-1 -> 0.43673167 | G15: =+G14/F14-1 -> 0.037125076 | H15: =+H14/G14-1 -> 0.037200876 | I15: =+I14/H14-1 -> 0.029343659 | J15: =+J14/I14-1 -> 0.032451131 | K15: =+K14/J14-1 -> 0.039076893 | L15: =+L14/K14-1 -> 0.043043048
C17: Gross Profit | E17: =+'Financial Statement Model'!D16 -> 974389 | F17: =+'Financial Statement Model'!E16 -> 1486719 | G17: =+'Financial Statement Model'!F16 -> 1603820 | H17: =+'Financial Statement Model'!G16 -> 1670261.8 | I17: =+'Financial Statement Model'!H16 -> 1747003.6 | J17: =+'Financial Statement Model'!I16 -> 1815147.8 | K17: =+'Financial Statement Model'!J16 -> 1897977.7 | L17: =+'Financial Statement Model'!K16 -> 1992084.2
C18: Gross Margin (%) | E18: =+E17/E$14 -> 0.27949832 | F18: =+F17/F$14 -> 0.29682471 | G18: =+G17/G$14 -> 0.30874196 | H18: =+H17/H$14 -> 0.31 | I18: =+I17/I$14 -> 0.315 | J18: =+J17/J$14 -> 0.317 | K18: =+K17/K$14 -> 0.319 | L18: =+L17/L$14 -> 0.321
C20: EBITDA | E20: =+'Financial Statement Model'!D29 -> 571682 | F20: =+'Financial Statement Model'!E29 -> 921799 | G20: =+'Financial Statement Model'!F29 -> 1027903 | H20: =+'Financial Statement Model'!G29 -> 942889.7 | I20: =+'Financial Statement Model'!H29 -> 998287.75 | J20: =+'Financial Statement Model'!I29 -> 1042135.4 | K20: =+'Financial Statement Model'!J29 -> 1094758.3 | L20: =+'Financial Statement Model'!K29 -> 1154291.8 | N20: =+_xlfn.RRI(YEAR($L$12)-YEAR($G$12),G20,L20) -> 0.023464291
C21: EBITDA Margin (%) | E21: =+E20/E$14 -> 0.16398395 | F21: =+F20/F$14 -> 0.18403795 | G21: =+G20/G$14 -> 0.19787556 | H21: =+H20/H$14 -> 0.175 | I21: =+I20/I$14 -> 0.18 | J21: =+J20/J$14 -> 0.182 | K21: =+K20/K$14 -> 0.184 | L21: =+L20/L$14 -> 0.186
C23: Operating Profit (EBIT) | E23: =+'Financial Statement Model'!D19 -> 492292 | F23: =+'Financial Statement Model'!E19 -> 798464 | G23: =+'Financial Statement Model'!F19 -> 895025 | H23: =+'Financial Statement Model'!G19 -> 942889.7 | I23: =+'Financial Statement Model'!H19 -> 998287.75 | J23: =+'Financial Statement Model'!I19 -> 1042135.4 | K23: =+'Financial Statement Model'!J19 -> 1094758.3 | L23: =+'Financial Statement Model'!K19 -> 1154291.8
C24: EBIT Margin (%) | E24: =+E23/E$14 -> 0.14121135 | F24: =+F23/F$14 -> 0.15941402 | G24: =+G23/G$14 -> 0.172296 | H24: =+H23/H$14 -> 0.175 | I24: =+I23/I$14 -> 0.18 | J24: =+J23/J$14 -> 0.182 | K24: =+K23/K$14 -> 0.184 | L24: =+L23/L$14 -> 0.186
C26: Tax on EBIT | E26: =+E23*E27 -> 124284.02 | F26: =+F23*F27 -> 200274.72 | G26: =+G23*G27 -> 229023.78 | H26: =+H23*H27 -> 241271.65 | I26: =+I23*I27 -> 255447.2 | J26: =+J23*J27 -> 266667.16 | K26: =+K23*K27 -> 280132.61 | L26: =+L23*L27 -> 295366.35
C27: Tax Rate (%) | E27: =+'Financial Statement Model'!D41 -> 0.25245995 | F27: =+'Financial Statement Model'!E41 -> 0.25082498 | G27: =+'Financial Statement Model'!F41 -> 0.25588534 | H27: =+'Financial Statement Model'!G41 -> 0.25588534 | I27: =+'Financial Statement Model'!H41 -> 0.25588534 | J27: =+'Financial Statement Model'!I41 -> 0.25588534 | K27: =+'Financial Statement Model'!J41 -> 0.25588534 | L27: =+'Financial Statement Model'!K41 -> 0.25588534
C29: NOPAT/EBIAT
C31: Plus: Depreciation and Amortization
C32: Plus: Stock Compensation
C33: Less: Change in Net Working Capital
C34: Less: Capital Expenditures & Acquisition Spend
C36: Unlevered Free Cash Flow (UFCF) | N36: =+_xlfn.RRI(YEAR($L$12)-YEAR($G$12),G36,L36) -> 0
C38: Net Working Capital Schedule | E38: Historical | H38: Projected
E39: ='Financial Statement Model'!D12 -> 44561 | F39: ='Financial Statement Model'!E12 -> 44926 | G39: ='Financial Statement Model'!F12 -> 45291 | H39: ='Financial Statement Model'!G12 -> 45657 | I39: ='Financial Statement Model'!H12 -> 46022 | J39: ='Financial Statement Model'!I12 -> 46387 | K39: ='Financial Statement Model'!J12 -> 46752 | L39: ='Financial Statement Model'!K12 -> 47118
C41: Short-Term Receivables | E41: =+'Financial Statement Model'!D47 -> 668419 | F41: =+'Financial Statement Model'!E47 -> 836071 | G41: =+'Financial Statement Model'!F47 -> 799009 | H41: =+'Financial Statement Model'!G47 -> 0 | I41: =+'Financial Statement Model'!H47 -> 0 | J41: =+'Financial Statement Model'!I47 -> 0 | K41: =+'Financial Statement Model'!J47 -> 0 | L41: =+'Financial Statement Model'!K47 -> 0
C42: Inventories | E42: =+'Financial Statement Model'!D48 -> 352801 | F42: =+'Financial Statement Model'!E48 -> 438644 | G42: =+'Financial Statement Model'!F48 -> 364731 | H42: =+'Financial Statement Model'!G48 -> 0 | I42: =+'Financial Statement Model'!H48 -> 0 | J42: =+'Financial Statement Model'!I48 -> 0 | K42: =+'Financial Statement Model'!J48 -> 0 | L42: =+'Financial Statement Model'!K48 -> 0
C43: Other Current Assets | E43: =+'Financial Statement Model'!D49 -> 26692 | F43: =+'Financial Statement Model'!E49 -> 34257 | G43: =+'Financial Statement Model'!F49 -> 36939 | H43: =+'Financial Statement Model'!G49 -> 0 | I43: =+'Financial Statement Model'!H49 -> 0 | J43: =+'Financial Statement Model'!I49 -> 0 | K43: =+'Financial Statement Model'!J49 -> 0 | L43: =+'Financial Statement Model'!K49 -> 0
C44: Current Assets (Ex. Cash) | E44: =SUM(E41:E43) -> 1047912 | F44: =SUM(F41:F43) -> 1308972 | G44: =SUM(G41:G43) -> 1200679 | H44: =SUM(H41:H43) -> 0 | I44: =SUM(I41:I43) -> 0 | J44: =SUM(J41:J43) -> 0 | K44: =SUM(K41:K43) -> 0 | L44: =SUM(L41:L43) -> 0
C46: Accounts Payable | E46: =+'Financial Statement Model'!D59 -> 461917 | F46: =+'Financial Statement Model'!E59 -> 487114 | G46: =+'Financial Statement Model'!F59 -> 469585 | H46: =+'Financial Statement Model'!G59 -> 0 | I46: =+'Financial Statement Model'!H59 -> 0 | J46: =+'Financial Statement Model'!I59 -> 0 | K46: =+'Financial Statement Model'!J59 -> 0 | L46: =+'Financial Statement Model'!K59 -> 0
C47: Other Current Liabilities | E47: =+'Financial Statement Model'!D61 -> 175891 | F47: =+'Financial Statement Model'!E61 -> 199370 | G47: =+'Financial Statement Model'!F61 -> 187217 | H47: =+'Financial Statement Model'!G61 -> 0 | I47: =+'Financial Statement Model'!H61 -> 0 | J47: =+'Financial Statement Model'!I61 -> 0 | K47: =+'Financial Statement Model'!J61 -> 0 | L47: =+'Financial Statement Model'!K61 -> 0
C48: Current Liabilities | E48: =SUM(E46:E47) -> 637808 | F48: =SUM(F46:F47) -> 686484 | G48: =SUM(G46:G47) -> 656802 | H48: =SUM(H46:H47) -> 0 | I48: =SUM(I46:I47) -> 0 | J48: =SUM(J46:J47) -> 0 | K48: =SUM(K46:K47) -> 0 | L48: =SUM(L46:L47) -> 0
C50: Net Working Capital | E50: =+E44-E48 -> 410104 | F50: =+F44-F48 -> 622488 | G50: =+G44-G48 -> 543877 | H50: =+H44-H48 -> 0 | I50: =+I44-I48 -> 0 | J50: =+J44-J48 -> 0 | K50: =+K44-K48 -> 0 | L50: =+L44-L48 -> 0
C52: Change in Net Working Capital | F52: =+F50-E50 -> 212384 | G52: =+G50-F50 -> -78611 | H52: =+H50-G50 -> -543877 | I52: =+I50-H50 -> 0 | J52: =+J50-I50 -> 0 | K52: =+K50-J50 -> 0 | L52: =+L50-K50 -> 0
C54: ="Present Value of UFCFs as of "&TEXT(D7,("mmm dd, yyyy")) -> Present Value of UFCFs as of Apr 12, 2024 | F54: Stub % | H54: Stub Year | I54: Year 2 | J54: Year 3 | K54: Year 4 | L54: Year 5
C55: Dates for Discounting UFCF
C57: Periods for Discounting UFCF | P57: Use Actual/Actual convention for Periods and Stub %
C59: Stub-adjusted Unlevered Free Cash Flow (UFCF) | P59: Factor in Y1 UFCF for the Stub Rate
...

Sheet WACC Build
C2: ="WACC Build For "&D5 -> WACC Build For TopBuild Corp.
C3: $ in thousands except per share | J3: Values
C5: Company Name | D5: ='Revenue Build & Growth Drivers'!D5 -> TopBuild Corp. | G5: Basic Shares Outstanding | J5: =+'Integrated DCF Model'!D66 -> 31775.877
C6: Ticker | D6: ='Revenue Build & Growth Drivers'!D6 -> BLD | G6: Fully Diluted Shares Outstanding | J6: =+'Integrated DCF Model'!D71 -> 32100.077
C7: Valuation Date | D7: ='Revenue Build & Growth Drivers'!D7 -> 45394
C8: Latest Adj. Closing Share Price Date | D8: ='Revenue Build & Growth Drivers'!D8 -> 45393
C9: Latest Adj. Closing Share Price | D9: ='Revenue Build & Growth Drivers'!D9 -> 421.45
C11: Cost of Debt Calculation | F11: Beta (β) Calculator
C14: Total Interest Expenses | F14: =D5&" ("&D6&")" -> TopBuild Corp. (BLD) | J14: S&P 500 Index | N14: Exclude operating leases from cost of debt and capital structure weight calculations.
F15: Date | G15: Adj. Close Price | H15: Return (%) | J15: Date | K15: Adj. Close Price | L15: Return (%)
C16: Short-term Bank Credit/Revolver | F16: 44287 | G16: 222.38 | J16: 44287 | K16: 4181.17
C17: Current Portion of LT Debt & Finance leases | F17: 44317 | G17: 198.05 | H17: =+G17/G16-1 -> -0.10940732 | J17: 44317 | K17: 4204.11 | L17: =+K17/K16-1 -> 0.0054865026
C18: LT Debt & Finance leases (Ex. Current Portion) | F18: 44348 | G18: 197.78 | H18: =+G18/G17-1 -> -0.0013632921 | J18: 44348 | K18: 4297.5 | L18: =+K18/K17-1 -> 0.022213976
C19: Total Debt | F19: 44378 | G19: 202.69 | H19: =+G19/G18-1 -> 0.024825564 | J19: 44378 | K19: 4395.26 | L19: =+K19/K18-1 -> 0.022748109
F20: 44409 | G20: 218.79 | H20: =+G20/G19-1 -> 0.079431644 | J20: 44409 | K20: 4522.68 | L20: =+K20/K19-1 -> 0.028990321
C21: Pre-tax Cost of Debt | F21: 44440 | G21: 204.81 | H21: =+G21/G20-1 -> -0.063896887 | J21: 44440 | K21: 4307.54 | L21: =+K21/K20-1 -> -0.04756914
C22: Effective Tax Rate | F22: 44470 | G22: 256.97 | H22: =+G22/G21-1 -> 0.25467506 | J22: 44470 | K22: 4605.38 | L22: =+K22/K21-1 -> 0.069143873
F23: 44501 | G23: 269.79 | H23: =+G23/G22-1 -> 0.049889092 | J23: 44501 | K23: 4567 | L23: =+K23/K22-1 -> -0.0083337314
C24: Effective Cost of Debt | F24: 44531 | G24: 275.91 | H24: =+G24/G23-1 -> 0.02268431 | J24: 44531 | K24: 4766.18 | L24: =+K24/K23-1 -> 0.043612875 | N24: Use 2023 effective tax rate. If negative, take average of the positive values from historical periods.
F25: 44562 | G25: 232.65 | H25: =+G25/G24-1 -> -0.15679026 | J25: 44562 | K25: 4515.55 | L25: =+K25/K24-1 -> -0.052585089
C26: Cost of Equity Calculation | F26: 44593 | G26: 214.68 | H26: =+G26/G25-1 -> -0.07724049 | J26: 44593 | K26: 4373.94 | L26: =+K26/K25-1 -> -0.031360521
F27: 44621 | G27: 181.39 | H27: =+G27/G26-1 -> -0.15506801 | J27: 44621 | K27: 4530.41 | L27: =+K27/K26-1 -> 0.035773239
F28: 44652 | G28: 181.14 | H28: =+G28/G27-1 -> -0.0013782458 | J28: 44652 | K28: 4131.93 | L28: =+K28/K27-1 -> -0.087956719
C29: Equity Risk Premium | D29: 0.0413 | F29: 44682 | G29: 197.26 | H29: =+G29/G28-1 -> 0.08899194 | J29: 44682 | K29: 4132.15 | L29: =+K29/K28-1 -> 5.3243884e-05
C30: Risk-free Rate | D30: 0.0456 | F30: 44713 | G30: 167.16 | H30: =+G30/G29-1 -> -0.15259049 | J30: 44713 | K30: 3785.38 | L30: =+K30/K29-1 -> -0.083919993
C31: Company Beta | F31: 44743 | G31: 211.72 | H31: =+G31/G30-1 -> 0.26657095 | J31: 44743 | K31: 4130.29 | L31: =+K31/K30-1 -> 0.091116348
F32: 44774 | G32: 183.76 | H32: =+G32/G31-1 -> -0.13206121 | J32: 44774 | K32: 3955 | L32: =+K32/K31-1 -> -0.042440119
C33: Cost of Equity | F33: 44805 | G33: 164.78 | H33: =+G33/G32-1 -> -0.1032869 | J33: 44805 | K33: 3585.62 | L33: =+K33/K32-1 -> -0.093395702
F34: 44835 | G34: 170.14 | H34: =+G34/G33-1 -> 0.032528219 | J34: 44835 | K34: 3871.98 | L34: =+K34/K33-1 -> 0.079863455
C35: Capital Structure and WACC | F35: 44866 | G35: 154.08 | H35: =+G35/G34-1 -> -0.094392853 | J35: 44866 | K35: 4080.11 | L35: =+K35/K34-1 -> 0.05375286
F36: 44896 | G36: 156.49 | H36: =+G36/G35-1 -> 0.015641225 | J36: 44896 | K36: 3839.5 | L36: =+K36/K35-1 -> -0.058971449
F37: 44927 | G37: 200.06 | H37: =+G37/G36-1 -> 0.27842035 | J37: 44927 | K37: 4076.6 | L37: =+K37/K36-1 -> 0.061752832
C38: Total Debt | F38: 44958 | G38: 207.59 | H38: =+G38/G37-1 -> 0.037638708 | J38: 44958 | K38: 3970.15 | L38: =+K38/K37-1 -> -0.026112447
C39: % of Total Capital | F39: 44986 | G39: 208.14 | H39: =+G39/G38-1 -> 0.0026494532 | J39: 44986 | K39: 4109.31 | L39: =+K39/K38-1 -> 0.035051572
C40: Equity Value | F40: 45017 | G40: 225.48 | H40: =+G40/G39-1 -> 0.083309311 | J40: 45017 | K40: 4169.48 | L40: =+K40/K39-1 -> 0.014642361
C41: % of Total Capital | F41: 45047 | G41: 201.66 | H41: =+G41/G40-1 -> -0.1056413 | J41: 45047 | K41: 4179.83 | L41: =+K41/K40-1 -> 0.0024823239
F42: 45078 | G42: 266.02 | H42: =+G42/G41-1 -> 0.31915105 | J42: 45078 | K42: 4450.38 | L42: =+K42/K41-1 -> 0.064727513
C43: Weighted Average Cost of Capital (WACC) | F43: 45108 | G43: 273.93 | H43: =+G43/G42-1 -> 0.029734606 | J43: 45108 | K43: 4588.96 | L43: =+K43/K42-1 -> 0.031138914
F44: 45139 | G44: 290.08 | H44: =+G44/G43-1 -> 0.058956668 | J44: 45139 | K44: 4507.66 | L44: =+K44/K43-1 -> -0.017716432
F45: 45170 | G45: 251.6 | H45: =+G45/G44-1 -> -0.13265306 | J45: 45170 | K45: 4288.05 | L45: =+K45/K44-1 -> -0.048719291
...
